Workbook
Name delete: OFFSET(#REF!,0,0,MATCH(REPT("z",255),#REF!),1)
Name items: OFFSET(#REF!,0,0,MATCH(REPT("z",255),#REF!),1)
Name unkbown: OFFSET(#REF!,0,0,MATCH(REPT("z",255),#REF!),1)
Name unknown: OFFSET(#REF!,0,0,MATCH(REPT("z",255),#REF!),1)
Name valuevx: 42.314159
Name delete: OFFSET(#REF!,0,0,MATCH(REPT("z",255),#REF!),1)
Name items: OFFSET(#REF!,0,0,MATCH(REPT("z",255),#REF!),1)
Name unkbown: OFFSET(#REF!,0,0,MATCH(REPT("z",255),#REF!),1)
Name unknown: OFFSET(#REF!,0,0,MATCH(REPT("z",255),#REF!),1)

Sheet DRT Quote Template
C5: 2430 W Broadway, Vancouver BC, V6K 2E7
A7: Project:
A9: Total Quoted Price: | B9: =SUM(G17:G33)
A11: Description: | B11: - Remove or adjust stud framed and tbar ceilings as required to access joists
B16: Material Code | C16: Description | D16: Quantity | E16: Units | F16: Rate | G16: Cost
A17: Material | B17: 253st | C17: =IFERROR(VLOOKUP(B17,'List of Material Kenroc'!$E$3:F325,2,FALSE),0) | D17: 5 | E17: =VLOOKUP(B17,'List of Material Kenroc'!$H$3:I326,2,FALSE) | F17: =IFERROR(VLOOKUP(B17,'List of Material Kenroc'!$B$3:$C$326,2,FALSE),0)*1.15 | G17: =F17*D17
B18: 253t | C18: =IFERROR(VLOOKUP(B18,'List of Material Kenroc'!$E$3:F326,2,FALSE),0) | E18: =VLOOKUP(B18,'List of Material Kenroc'!$H$3:I327,2,FALSE) | F18: =IFERROR(VLOOKUP(B18,'List of Material Kenroc'!$B$3:$C$326,2,FALSE),0)*1.15 | G18: =F18*D18
B19: 253s | C19: =IFERROR(VLOOKUP(B19,'List of Material Kenroc'!$E$3:F327,2,FALSE),0) | E19: =VLOOKUP(B19,'List of Material Kenroc'!$H$3:I328,2,FALSE) | F19: =IFERROR(VLOOKUP(B19,'List of Material Kenroc'!$B$3:$C$326,2,FALSE),0)*1.15 | G19: =F19*D19
B20: 12std | C20: =IFERROR(VLOOKUP(B20,'List of Material Kenroc'!$E$3:F328,2,FALSE),0) | E20: =VLOOKUP(B20,'List of Material Kenroc'!$H$3:I329,2,FALSE) | F20: =IFERROR(VLOOKUP(B20,'List of Material Kenroc'!$B$3:$C$326,2,FALSE),0)*1.15 | G20: =F20*D20
B21: r12 | C21: =IFERROR(VLOOKUP(B21,'List of Material Kenroc'!$E$3:F329,2,FALSE),0) | E21: =VLOOKUP(B21,'List of Material Kenroc'!$H$3:I330,2,FALSE) | F21: =IFERROR(VLOOKUP(B21,'List of Material Kenroc'!$B$3:$C$326,2,FALSE),0)*1.15 | G21: =F21*D21
B22: tm | C22: =IFERROR(VLOOKUP(B22,'List of Material Kenroc'!$E$3:F330,2,FALSE),0) | E22: =VLOOKUP(B22,'List of Material Kenroc'!$H$3:I329,2,FALSE) | F22: =IFERROR(VLOOKUP(B22,'List of Material Kenroc'!$B$3:$C$326,2,FALSE),0)*1.15 | G22: =F22*D22
B23: 256st | C23: =IFERROR(VLOOKUP(B23,'List of Material Kenroc'!$E$3:F327,2,FALSE),0) | D23: 2 | E23: =VLOOKUP(B23,'List of Material Kenroc'!$H$3:I326,2,FALSE) | F23: =IFERROR(VLOOKUP(B23,'List of Material Kenroc'!$B$3:$C$326,2,FALSE),0)*1.15 | G23: =F23*D23
B24: 252s | C24: =IFERROR(VLOOKUP(B24,'List of Material Kenroc'!$E$3:F328,2,FALSE),0) | E24: =VLOOKUP(B24,'List of Material Kenroc'!$H$3:I327,2,FALSE) | F24: =IFERROR(VLOOKUP(B24,'List of Material Kenroc'!$B$3:$C$326,2,FALSE),0)*1.15 | G24: =F24*D24
C25: =IFERROR(VLOOKUP(B25,'List of Material Kenroc'!$E$3:F329,2,FALSE),0) | E25: =VLOOKUP(B25,'List of Material Kenroc'!$H$3:I328,2,FALSE) | F25: =IFERROR(VLOOKUP(B25,'List of Material Kenroc'!$B$3:$C$326,2,FALSE),0)*1.15 | G25: =F25*D25
C26: =IFERROR(VLOOKUP(B26,'List of Material Kenroc'!$E$3:F330,2,FALSE),0) | E26: =VLOOKUP(B26,'List of Material Kenroc'!$H$3:I329,2,FALSE) | F26: =IFERROR(VLOOKUP(B26,'List of Material Kenroc'!$B$3:$C$326,2,FALSE),0)*1.15 | G26: =F26*D26
C27: =IFERROR(VLOOKUP(B27,'List of Material Kenroc'!$E$3:F331,2,FALSE),0) | E27: =VLOOKUP(B27,'List of Material Kenroc'!$H$3:I330,2,FALSE) | F27: =IFERROR(VLOOKUP(B27,'List of Material Kenroc'!$B$3:$C$326,2,FALSE),0)*1.15 | G27: =F27*D27
A29: Labour | B29: vghl | C29: =IFERROR(VLOOKUP(B29,'List of Material Kenroc'!$E$3:F333,2,FALSE),0) | E29: =VLOOKUP(B29,'List of Material Kenroc'!$H$3:I331,2,FALSE) | F29: =IFERROR(VLOOKUP(B29,'List of Material Kenroc'!$B$3:$C$326,2,FALSE),0) | G29: =F29*D29
B30: vghl | C30: =IFERROR(VLOOKUP(B30,'List of Material Kenroc'!$E$3:F334,2,FALSE),0) | E30: =VLOOKUP(B30,'List of Material Kenroc'!$H$3:I332,2,FALSE) | F30: =IFERROR(VLOOKUP(B30,'List of Material Kenroc'!$B$3:$C$326,2,FALSE),0) | G30: =F30*D30
B31: vghl | C31: =IFERROR(VLOOKUP(B31,'List of Material Kenroc'!$E$3:F335,2,FALSE),0) | E31: =VLOOKUP(B31,'List of Material Kenroc'!$H$3:I333,2,FALSE) | F31: =IFERROR(VLOOKUP(B31,'List of Material Kenroc'!$B$3:$C$326,2,FALSE),0) | G31: =F31*D31
B32: d | C32: =IFERROR(VLOOKUP(B32,'List of Material Kenroc'!$E$3:F334,2,FALSE),0) | E32: =VLOOKUP(B32,'List of Material Kenroc'!$H$3:I337,2,FALSE) | F32: =IFERROR(VLOOKUP(B32,'List of Material Kenroc'!$B$3:$C$326,2,FALSE),0)*1.3 | G32: =F32*D32
B33: df | C33: =IFERROR(VLOOKUP(B33,'List of Material Kenroc'!$E$3:F335,2,FALSE),0) | E33: =VLOOKUP(B33,'List of Material Kenroc'!$H$3:I338,2,FALSE) | F33: =IFERROR(VLOOKUP(B33,'List of Material Kenroc'!$B$3:$C$326,2,FALSE),0)*1.3 | G33: =F33*D33

Sheet List of Material Kenroc
A1: Item | B1: Material Code | C1: Price
A3: 1/4” Flex | B3: 14f | C3: 0.6 | E3: 14f | F3: =A3 | H3: 14f | I3: Sqft
A4: 1/2” Std | B4: 12std | C4: 0.465 | E4: 12std | F4: =A4 | H4: 12std | I4: Sqft
A5: 1/2” CD | B5: 12cd | C5: 0.63 | E5: 12cd | F5: =A5 | H5: 12cd | I5: Sqft
A6: 1/2” Std 54” | B6: 54STD | C6: 0.628 | E6: 54STD | F6: =A6 | H6: 54STD | I6: Sqft
A7: 1/2” Type C | B7: 12tc | C7: 0.578 | E7: 12tc | F7: =A7 | H7: 12tc | I7: Sqft
A8: 1/2” Mould Resistant | B8: 12mr | C8: 1.215 | E8: 12mr | F8: =A8 | H8: 12mr | I8: Sqft
A9: 5/8” Type X | B9: 58tx | C9: 0.578 | E9: 58tx | F9: =A9 | H9: 58tx | I9: Sqft
A10: 5/8” Mould Resistant | B10: 58mr | C10: 1.415 | E10: 58mr | F10: =A10 | H10: 58mr | I10: Sqft
A11: 5/8” Type X 54” | B11: 54tx | C11: ? | E11: 54tx | F11: =A11 | H11: 54tx | I11: Sqft
A12: 5/8” Type C | B12: 58tc | C12: 0.578 | E12: 58tc | F12: =A12 | H12: 58tc | I12: Sqft
A13: 1/2” GlassRoc | B13: 12gr | C13: 1.28 | E13: 12gr | F13: =A13 | H13: 12gr | I13: Sqft
A14: 5/8” GlassRoc | B14: 58gr | C14: 1.39 | E14: 58gr | F14: =A14 | H14: 58gr | I14: Sqft
A15: 1/2” DiamondBacker | B15: 12db | C15: 2.22 | E15: 12db | F15: =A15 | H15: 12db | I15: Sqft
A16: 5/8” DiamondBacker | B16: 58db | C16: 2.71 | E16: 58db | F16: =A16 | H16: 58db | I16: Sqft
A17: 1” GlassRoc ShaftLiner | B17: 1grsl | C17: 2.17 | E17: 1grsl | F17: =A17 | H17: 1grsl | I17: Sqft
A18: 1” M2 Tech Shaftliner | B18: 1m2sl | C18: 1.89 | E18: 1m2sl | F18: =A18 | H18: 1m2sl | I18: Sqft
A19: 1/2” Durock Tile Backer | B19: 12dr | C19: 2.25 | E19: 12dr | F19: =A19 | H19: 12dr | I19: Sqft
A20: 5/8” Durock Tile Backer | B20: 58dr | C20: 2.761 | E20: 58dr | F20: =A20 | H20: 58dr | I20: Sqft
A21: 3/4" Plywood | B21: 34pw | C21: 4 | E21: 34pw | F21: =A21 | H21: 34pw | I21: Sqft
A22: 5/8" Plywood | B22: 58pw | C22: 3.5 | E22: 58pw | F22: =A22 | H22: 58pw | I22: Sqft
A23: 1/2" Fire Rated Plywood | B23: 12pw | C23: 3 | E23: 12pw | F23: =A23 | H23: 12pw | I23: Sqft
A24: QuietRock 550 | B24: qt530 | C24: ? | E24: qt530 | F24: =A24 | H24: qt530 | I24: Sqft
A25: 1/2" QuietRock 510 | B25: 12qt | C25: ? | E25: 12qt | F25: =A25 | H25: 12qt | I25: Sqft
A26: 1/2" QuietRock MR 510 | B26: 12qtmr | C26: ? | E26: 12qtmr | F26: =A26 | H26: 12qtmr | I26: Sqft
A27: 5/8" QuietRock EZ Snap | B27: 58qt | C27: ? | E27: 58qt | F27: =A27 | H27: 58qt | I27: Sqft
A28: 5/8" QuietRock MR EZ Snap | B28: 58qtmr | C28: ? | E28: 58qtmr | F28: =A28 | H28: 58qtmr | I28: Sqft
A29: 1/2" Abuse Resistant | B29: 12ar | C29: ? | E29: 12ar | F29: =A29 | H29: 12ar | I29: Sqft
A30: 5/8" Abuse Resistant - Type X | B30: 58ar | C30: ? | E30: 58ar | F30: =A30 | H30: 58ar | I30: Sqft
F31: =A31 | I31: Sqft
A32: R8 Insulation | B32: r8 | C32: 0.275 | E32: r8 | F32: =A32 | H32: r8 | I32: Sqft
A33: R12 Insulation | B33: r12 | C33: 0.44 | E33: r12 | F33: =A33 | H33: r12 | I33: Sqft
A34: R20 Insulation | B34: r20 | C34: 0.66 | E34: r20 | F34: =A34 | H34: r20 | I34: Sqft
A35: R12 QUIET ZONE | B35: R12QZ | C35: 0.44 | E35: R12QZ | F35: =A35 | H35: R12QZ | I35: Sqft
A36: R20 QUIET ZONE | B36: R20QZ | C36: 0.66 | E36: R20QZ | F36: =A36 | H36: R20QZ | I36: Sqft
A37: R28 Insulation | B37: r28 | C37: 0.915 | E37: r28 | F37: =A37 | H37: r28 | I37: Sqft
A38: R35 Insulation | B38: r35 | C38: ? | E38: r35 | F38: =A38 | H38: r35 | I38: Sqft
A39: R40 Insulation | B39: r40 | C39: 2.095 | E39: r40 | F39: =A39 | H39: r40 | I39: Sqft
A40: Roxul Comfort Batt R10 | B40: R10 | C40: ? | E40: R10 | F40: =A40 | H40: R10 | I40: Sqft
A41: Roxul Comfort Batt R14 | B41: R14 | C41: ? | E41: R14 | F41: =A41 | H41: R14 | I41: Sqft
...

Sheet List of Material Pacific West
A1: Item | B1: Material Code | C1: Price
A3: 1/4” Flex | B3: 14f | C3: 0.6 | E3: 14f | F3: =A3 | H3: 14f | I3: Sqft
A4: 1/2” Std | B4: 12std | C4: 0.465 | E4: 12std | F4: =A4 | H4: 12std | I4: Sqft
A5: 1/2” CD | B5: 12cd | C5: 0.63 | E5: 12cd | F5: =A5 | H5: 12cd | I5: Sqft
A6: 1/2” Std 54” | B6: 54STD | C6: 0.628 | E6: 54STD | F6: =A6 | H6: 54STD | I6: Sqft
A7: 1/2” Type C | B7: 12tc | C7: 0.578 | E7: 12tc | F7: =A7 | H7: 12tc | I7: Sqft
A8: 1/2” Mould Resistant | B8: 12mr | C8: 1.215 | E8: 12mr | F8: =A8 | H8: 12mr | I8: Sqft
A9: 5/8” Type X | B9: 58tx | C9: 0.578 | E9: 58tx | F9: =A9 | H9: 58tx | I9: Sqft
A10: 5/8” Mould Resistant | B10: 58mr | C10: 1.415 | E10: 58mr | F10: =A10 | H10: 58mr | I10: Sqft
A11: 5/8” Type X 54” | B11: 54tx | C11: ? | E11: 54tx | F11: =A11 | H11: 54tx | I11: Sqft
A12: 5/8” Type C | B12: 58tc | C12: 0.578 | E12: 58tc | F12: =A12 | H12: 58tc | I12: Sqft
A13: 1/2” GlassRoc | B13: 12gr | C13: 1.28 | E13: 12gr | F13: =A13 | H13: 12gr | I13: Sqft
A14: 5/8” GlassRoc | B14: 58gr | C14: 1.39 | E14: 58gr | F14: =A14 | H14: 58gr | I14: Sqft
A15: 1/2” DiamondBacker | B15: 12db | C15: 2.22 | E15: 12db | F15: =A15 | H15: 12db | I15: Sqft
A16: 5/8” DiamondBacker | B16: 58db | C16: 2.71 | E16: 58db | F16: =A16 | H16: 58db | I16: Sqft
A17: 1” GlassRoc ShaftLiner | B17: 1grsl | C17: 2.17 | E17: 1grsl | F17: =A17 | H17: 1grsl | I17: Sqft
A18: 1” M2 Tech Shaftliner | B18: 1m2sl | C18: 1.89 | E18: 1m2sl | F18: =A18 | H18: 1m2sl | I18: Sqft
A19: 1/2” Durock Tile Backer | B19: 12dr | C19: 2.25 | E19: 12dr | F19: =A19 | H19: 12dr | I19: Sqft
A20: 5/8” Durock Tile Backer | B20: 58dr | C20: 2.761 | E20: 58dr | F20: =A20 | H20: 58dr | I20: Sqft
A21: 3/4" Plywood | B21: 34pw | C21: 4 | E21: 34pw | F21: =A21 | H21: 34pw | I21: Sqft
A22: 5/8" Plywood | B22: 58pw | C22: 3.5 | E22: 58pw | F22: =A22 | H22: 58pw | I22: Sqft
A23: 1/2" Fire Rated Plywood | B23: 12pw | C23: 3 | E23: 12pw | F23: =A23 | H23: 12pw | I23: Sqft
A24: QuietRock 550 | B24: qt530 | C24: ? | E24: qt530 | F24: =A24 | H24: qt530 | I24: Sqft
A25: 1/2" QuietRock 510 | B25: 12qt | C25: ? | E25: 12qt | F25: =A25 | H25: 12qt | I25: Sqft
A26: 1/2" QuietRock MR 510 | B26: 12qtmr | C26: ? | E26: 12qtmr | F26: =A26 | H26: 12qtmr | I26: Sqft
A27: 5/8" QuietRock EZ Snap | B27: 58qt | C27: ? | E27: 58qt | F27: =A27 | H27: 58qt | I27: Sqft
A28: 5/8" QuietRock MR EZ Snap | B28: 58qtmr | C28: ? | E28: 58qtmr | F28: =A28 | H28: 58qtmr | I28: Sqft
A29: 1/2" Abuse Resistant | B29: 12ar | C29: ? | E29: 12ar | F29: =A29 | H29: 12ar | I29: Sqft
A30: 5/8" Abuse Resistant - Type X | B30: 58ar | C30: ? | E30: 58ar | F30: =A30 | H30: 58ar | I30: Sqft
F31: =A31 | I31: Sqft
A32: R8 Insulation | B32: r8 | C32: 0.275 | E32: r8 | F32: =A32 | H32: r8 | I32: Sqft
A33: R12 Insulation | B33: r12 | C33: 0.44 | E33: r12 | F33: =A33 | H33: r12 | I33: Sqft
A34: R20 Insulation | B34: r20 | C34: 0.66 | E34: r20 | F34: =A34 | H34: r20 | I34: Sqft
A35: R12 QUIET ZONE | B35: R12QZ | C35: 0.44 | E35: R12QZ | F35: =A35 | H35: R12QZ | I35: Sqft
A36: R20 QUIET ZONE | B36: R20QZ | C36: 0.66 | E36: R20QZ | F36: =A36 | H36: R20QZ | I36: Sqft
A37: R28 Insulation | B37: r28 | C37: 0.915 | E37: r28 | F37: =A37 | H37: r28 | I37: Sqft
A38: R35 Insulation | B38: r35 | C38: ? | E38: r35 | F38: =A38 | H38: r35 | I38: Sqft
A39: R40 Insulation | B39: r40 | C39: 2.095 | E39: r40 | F39: =A39 | H39: r40 | I39: Sqft
A40: Roxul Comfort Batt R10 | B40: R10 | C40: ? | E40: R10 | F40: =A40 | H40: R10 | I40: Sqft
A41: Roxul Comfort Batt R14 | B41: R14 | C41: ? | E41: R14 | F41: =A41 | H41: R14 | I41: Sqft
...

Sheet List of Material Dryco
A1: Item | B1: Material Code | C1: Price
A3: 1/4” Flex | B3: 14f | C3: 0.6 | E3: 14f | F3: =A3 | H3: 14f | I3: Sqft
A4: 1/2” Std | B4: 12std | C4: 0.455 | E4: 12std | F4: =A4 | H4: 12std | I4: Sqft
A5: 1/2” CD | B5: 12cd | C5: 0.63 | E5: 12cd | F5: =A5 | H5: 12cd | I5: Sqft
A6: 1/2” Std 54” | B6: 54STD | C6: 0.5827 | E6: 54STD | F6: =A6 | H6: 54STD | I6: Sqft
A7: 1/2” Type C | B7: 12tc | C7: 0.574 | E7: 12tc | F7: =A7 | H7: 12tc | I7: Sqft
A8: 1/2” Mould Resistant | B8: 12mr | C8: 1.1852 | E8: 12mr | F8: =A8 | H8: 12mr | I8: Sqft
A9: 5/8” Type X | B9: 58tx | C9: 0.555 | E9: 58tx | F9: =A9 | H9: 58tx | I9: Sqft
A10: 5/8” Mould Resistant | B10: 58mr | C10: 1.314 | E10: 58mr | F10: =A10 | H10: 58mr | I10: Sqft
A11: 5/8” Type X 54” | B11: 54tx | C11: 0.864 | E11: 54tx | F11: =A11 | H11: 54tx | I11: Sqft
A12: 5/8” Type C | B12: 58tc | C12: 0.555 | E12: 58tc | F12: =A12 | H12: 58tc | I12: Sqft
A13: 1/2” GlassRoc | B13: 12gr | C13: 1.2169 | E13: 12gr | F13: =A13 | H13: 12gr | I13: Sqft
A14: 5/8” GlassRoc | B14: 58gr | C14: 1.3169 | E14: 58gr | F14: =A14 | H14: 58gr | I14: Sqft
... A23: 1/2" Fire Rated Plywood | B23: 12pw | C23: 3 | E23: 12pw | F23: =A23 | H23: 12pw | I23: Sqft
A24: QuietRock 550 | B24: qt530 | C24: ? | E24: qt530 | F24: =A24 | H24: qt530 | I24: Sqft
A25: 1/2" QuietRock 510 | B25: 12qt | C25: ? | E25: 12qt | F25: =A25 | H25: 12qt | I25: Sqft
A26: 1/2" QuietRock MR 510 | B26: 12qtmr | C26: ? | E26: 12qtmr | F26: =A26 | H26: 12qtmr | I26: Sqft
A27: 5/8" QuietRock EZ Snap | B27: 58qt | C27: ? | E27: 58qt | F27: =A27 | H27: 58qt | I27: Sqft
A28: 5/8" QuietRock MR EZ Snap | B28: 58qtmr | C28: ? | E28: 58qtmr | F28: =A28 | H28: 58qtmr | I28: Sqft
A29: 1/2" Abuse Resistant | B29: 12ar | C29: 1.2932 | E29: 12ar | F29: =A29 | H29: 12ar | I29: Sqft
A30: 5/8" Abuse Resistant - Type X | B30: 58ar | C30: 1.4988 | E30: 58ar | F30: =A30 | H30: 58ar | I30: Sqft
F31: =A31 | I31: Sqft
A32: R8 Insulation | B32: r8 | C32: 0.2703 | E32: r8 | F32: =A32 | H32: r8 | I32: Sqft
A33: R12 Insulation | B33: r12 | C33: 0.3716 | E33: r12 | F33: =A33 | H33: r12 | I33: Sqft
A34: R20 Insulation | B34: r20 | C34: 0.628 | E34: r20 | F34: =A34 | H34: r20 | I34: Sqft
A35: R12 QUIET ZONE | B35: R12QZ | C35: 1.3605 | E35: R12QZ | F35: =A35 | H35: R12QZ | I35: Sqft
A36: R20 QUIET ZONE | B36: R20QZ | C36: 1.257 | E36: R20QZ | F36: =A36 | H36: R20QZ | I36: Sqft
A37: R28 Insulation | B37: r28 | C37: 0.8289 | E37: r28 | F37: =A37 | H37: r28 | I37: Sqft
A38: R35 Insulation | B38: r35 | C38: 1.0347 | E38: r35 | F38: =A38 | H38: r35 | I38: Sqft
A39: R40 Insulation | B39: r40 | C39: 1.2731 | E39: r40 | F39: =A39 | H39: r40 | I39: Sqft
A40: Roxul Comfort Batt R10 | B40: R10 | C40: 0.9087 | E40: R10 | F40: =A40 | H40: R10 | I40: Sqft
A41: Roxul Comfort Batt R14 | B41: R14 | C41: 1.2785 | E41: R14 | F41: =A41 | H41: R14 | I41: Sqft
A42: Roxul Comfort Batt R22 | B42: R22 | C42: 2.0078 | E42: R22 | F42: =A42 | H42: R22 | I42: Sqft
A43: Roxul AFB 2 1/2" | B43: AFB25 | C43: 1.5197 | E43: AFB25 | F43: =A43 | H43: AFB25 | I43: Sqft
... A45: Roxul AFB 6" | B45: AFB6 | C45: 3.1726 | E45: AFB6 | F45: =A45 | H45: AFB6 | I45: Sqft
F46: =A46 | I46: Sqft
A47: 6 Mil Poly | B47: 6mil | C47: 0.07 | E47: 6mil | F47: =A47 | H47: 6mil | I47: Sqft
A48: Light Weight Poly | B48: lwp | C48: 15.74 | E48: lwp | F48: =A48 | H48: lwp | I48: Sqft
A49: 1 1/2” TYPE 4 RIGID | B49: 15T4R | C49: 1.22115 | E49: 15T4R | F49: =A49 | H49: 15T4R | I49: Sqft
A50: 2" Foil Back Insulation | B50: 2fb | C50: 3.8594 | E50: 2fb | F50: =A50 | H50: 2fb | I50: Sqft
...
